{"uuid": "d2d2a916-090f-4ae6-8215-c1b3f3f15386", "children": ["ed393dca-a131-4c9a-bea9-27ebd81874fd"], "befores": [{"name": "_xunit_setup_method_fixture_Test_testlogin", "status": "broken", "statusDetails": {"message": "TypeError: 'module' object is not callable\n", "trace": "  File \"E:\\python\\Python311\\Lib\\site-packages\\pluggy\\_callers.py\", line 39, in _multicall\n    res = hook_impl.function(*args)\n          ^^^^^^^^^^^^^^^^^^^^^^^^^\n  File \"E:\\python\\Python311\\Lib\\site-packages\\_pytest\\fixtures.py\", line 1129, in pytest_fixture_setup\n    result = call_fixture_func(fixturefunc, request, kwargs)\n             ^^^^^^^^^^^^^^^^^^^^^^^^^^^^^^^^^^^^^^^^^^^^^^^\n  File \"E:\\python\\Python311\\Lib\\site-packages\\_pytest\\fixtures.py\", line 901, in call_fixture_func\n    fixture_result = next(generator)\n                     ^^^^^^^^^^^^^^^\n  File \"E:\\python\\Python311\\Lib\\site-packages\\_pytest\\python.py\", line 907, in xunit_setup_method_fixture\n    _call_with_optional_argument(func, method)\n  File \"E:\\python\\Python311\\Lib\\site-packages\\_pytest\\python.py\", line 788, in _call_with_optional_argument\n    func()\n  File \"E:\\project\\pytest-allure\\TestCases\\test_login.py\", line 27, in setup\n    self.driver = webdriver.chrome()\n                  ^^^^^^^^^^^^^^^^^^\n"}, "start": 1685890331518, "stop": 1685890331518}], "start": 1685890331518, "stop": 1685890331581}